[2025-06-06T15:53:10.297+0000] {taskinstance.py:1956} INFO - Dependencies all met for dep_context=non-requeueable deps ti=<TaskInstance: rss_ingestion_dag.extract_and_load manual__2025-06-06T15:53:07.035841+00:00 [queued]>
[2025-06-06T15:53:10.305+0000] {taskinstance.py:1956} INFO - Dependencies all met for dep_context=requeueable deps ti=<TaskInstance: rss_ingestion_dag.extract_and_load manual__2025-06-06T15:53:07.035841+00:00 [queued]>
[2025-06-06T15:53:10.305+0000] {taskinstance.py:2170} INFO - Starting attempt 1 of 1
[2025-06-06T15:53:10.315+0000] {taskinstance.py:2191} INFO - Executing <Task(_PythonDecoratedOperator): extract_and_load> on 2025-06-06 15:53:07.035841+00:00
[2025-06-06T15:53:10.321+0000] {standard_task_runner.py:60} INFO - Started process 56 to run task
[2025-06-06T15:53:10.326+0000] {standard_task_runner.py:87} INFO - Running: ['***', 'tasks', 'run', 'rss_ingestion_dag', 'extract_and_load', 'manual__2025-06-06T15:53:07.035841+00:00', '--job-id', '5', '--raw', '--subdir', 'DAGS_FOLDER/rss_ingestion_dag.py', '--cfg-path', '/tmp/tmp8p58s03x']
[2025-06-06T15:53:10.330+0000] {standard_task_runner.py:88} INFO - Job 5: Subtask extract_and_load
[2025-06-06T15:53:10.391+0000] {task_command.py:423} INFO - Running <TaskInstance: rss_ingestion_dag.extract_and_load manual__2025-06-06T15:53:07.035841+00:00 [running]> on host 24ef933245e8
[2025-06-06T15:53:10.464+0000] {taskinstance.py:2480} INFO - Exporting env vars: AIRFLOW_CTX_DAG_OWNER='***' AIRFLOW_CTX_DAG_ID='rss_ingestion_dag' AIRFLOW_CTX_TASK_ID='extract_and_load' AIRFLOW_CTX_EXECUTION_DATE='2025-06-06T15:53:07.035841+00:00' AIRFLOW_CTX_TRY_NUMBER='1' AIRFLOW_CTX_DAG_RUN_ID='manual__2025-06-06T15:53:07.035841+00:00'
[2025-06-06T15:53:10.641+0000] {_metadata.py:139} WARNING - Compute Engine Metadata server unavailable on attempt 1 of 3. Reason: [Errno 111] Connection refused
[2025-06-06T15:53:10.642+0000] {_metadata.py:139} WARNING - Compute Engine Metadata server unavailable on attempt 2 of 3. Reason: [Errno 111] Connection refused
[2025-06-06T15:53:10.644+0000] {_metadata.py:139} WARNING - Compute Engine Metadata server unavailable on attempt 3 of 3. Reason: [Errno 111] Connection refused
[2025-06-06T15:53:10.645+0000] {_default.py:338} WARNING - Authentication failed using Compute Engine authentication due to unavailable metadata server.
[2025-06-06T15:53:10.645+0000] {taskinstance.py:2698} ERROR - Task failed with exception
Traceback (most recent call last):
  File "/home/airflow/.local/lib/python3.10/site-packages/airflow/models/taskinstance.py", line 433, in _execute_task
    result = execute_callable(context=context, **execute_callable_kwargs)
  File "/home/airflow/.local/lib/python3.10/site-packages/airflow/decorators/base.py", line 241, in execute
    return_value = super().execute(context)
  File "/home/airflow/.local/lib/python3.10/site-packages/airflow/operators/python.py", line 199, in execute
    return_value = self.execute_callable()
  File "/home/airflow/.local/lib/python3.10/site-packages/airflow/operators/python.py", line 216, in execute_callable
    return self.python_callable(*self.op_args, **self.op_kwargs)
  File "/opt/airflow/dags/rss_ingestion_dag.py", line 24, in extract_and_load
    existing_ids = get_existing_ids(table_id)
  File "/opt/airflow/src/ingestion/rss_fetcher.py", line 17, in get_existing_ids
    client = bigquery.Client()
  File "/home/airflow/.local/lib/python3.10/site-packages/google/cloud/bigquery/client.py", line 237, in __init__
    super(Client, self).__init__(
  File "/home/airflow/.local/lib/python3.10/site-packages/google/cloud/client/__init__.py", line 320, in __init__
    _ClientProjectMixin.__init__(self, project=project, credentials=credentials)
  File "/home/airflow/.local/lib/python3.10/site-packages/google/cloud/client/__init__.py", line 268, in __init__
    project = self._determine_default(project)
  File "/home/airflow/.local/lib/python3.10/site-packages/google/cloud/client/__init__.py", line 287, in _determine_default
    return _determine_default_project(project)
  File "/home/airflow/.local/lib/python3.10/site-packages/google/cloud/_helpers/__init__.py", line 152, in _determine_default_project
    _, project = google.auth.default()
  File "/home/airflow/.local/lib/python3.10/site-packages/google/auth/_default.py", line 691, in default
    raise exceptions.DefaultCredentialsError(_CLOUD_SDK_MISSING_CREDENTIALS)
google.auth.exceptions.DefaultCredentialsError: Your default credentials were not found. To set up Application Default Credentials, see https://cloud.google.com/docs/authentication/external/set-up-adc for more information.
[2025-06-06T15:53:10.659+0000] {taskinstance.py:1138} INFO - Marking task as FAILED. dag_id=rss_ingestion_dag, task_id=extract_and_load, execution_date=20250606T155307, start_date=20250606T155310, end_date=20250606T155310
[2025-06-06T15:53:10.671+0000] {standard_task_runner.py:107} ERROR - Failed to execute job 5 for task extract_and_load (Your default credentials were not found. To set up Application Default Credentials, see https://cloud.google.com/docs/authentication/external/set-up-adc for more information.; 56)
[2025-06-06T15:53:10.699+0000] {local_task_job_runner.py:234} INFO - Task exited with return code 1
[2025-06-06T15:53:10.714+0000] {taskinstance.py:3280} INFO - 0 downstream tasks scheduled from follow-on schedule check
