[2025-06-12T19:31:09.066+0000] {taskinstance.py:1956} INFO - Dependencies all met for dep_context=non-requeueable deps ti=<TaskInstance: score_missing_articles_pipeline.score_missing_articles manual__2025-06-12T19:31:03.658713+00:00 [queued]>
[2025-06-12T19:31:09.074+0000] {taskinstance.py:1956} INFO - Dependencies all met for dep_context=requeueable deps ti=<TaskInstance: score_missing_articles_pipeline.score_missing_articles manual__2025-06-12T19:31:03.658713+00:00 [queued]>
[2025-06-12T19:31:09.075+0000] {taskinstance.py:2170} INFO - Starting attempt 1 of 2
[2025-06-12T19:31:09.090+0000] {taskinstance.py:2191} INFO - Executing <Task(PythonOperator): score_missing_articles> on 2025-06-12 19:31:03.658713+00:00
[2025-06-12T19:31:09.104+0000] {standard_task_runner.py:60} INFO - Started process 153 to run task
[2025-06-12T19:31:09.110+0000] {standard_task_runner.py:87} INFO - Running: ['***', 'tasks', 'run', 'score_missing_articles_pipeline', 'score_missing_articles', 'manual__2025-06-12T19:31:03.658713+00:00', '--job-id', '351', '--raw', '--subdir', 'DAGS_FOLDER/score_missing_dag.py', '--cfg-path', '/tmp/tmp7ts5raoq']
[2025-06-12T19:31:09.116+0000] {standard_task_runner.py:88} INFO - Job 351: Subtask score_missing_articles
[2025-06-12T19:31:09.185+0000] {task_command.py:423} INFO - Running <TaskInstance: score_missing_articles_pipeline.score_missing_articles manual__2025-06-12T19:31:03.658713+00:00 [running]> on host ae5839759441
[2025-06-12T19:31:09.263+0000] {taskinstance.py:2480} INFO - Exporting env vars: AIRFLOW_CTX_DAG_OWNER='***' AIRFLOW_CTX_DAG_ID='score_missing_articles_pipeline' AIRFLOW_CTX_TASK_ID='score_missing_articles' AIRFLOW_CTX_EXECUTION_DATE='2025-06-12T19:31:03.658713+00:00' AIRFLOW_CTX_TRY_NUMBER='1' AIRFLOW_CTX_DAG_RUN_ID='manual__2025-06-12T19:31:03.658713+00:00'
[2025-06-12T19:31:11.356+0000] {score_missing_articles.py:36} INFO - Modèle chargé : ClassCat/gpt2-base-french
[2025-06-12T19:31:15.843+0000] {score_missing_articles.py:36} INFO - Modèle chargé : asi/gpt-fr-cased-base
[2025-06-12T19:31:19.682+0000] {score_missing_articles.py:36} INFO - Modèle chargé : asi/gpt-fr-cased-small
[2025-06-12T19:31:20.659+0000] {score_missing_articles.py:36} INFO - Modèle chargé : dbddv01/gpt2-french-small
[2025-06-12T19:31:22.467+0000] {score_missing_articles.py:45} INFO - 157 articles à traiter.
[2025-06-12T19:31:23.820+0000] {log.py:232} WARNING - `loss_type=None` was set in the config but it is unrecognised.Using the default loss: `ForCausalLMLoss`.
[2025-06-12T19:50:32.796+0000] {score_missing_articles.py:70} INFO - Préparation de la requête de mise à jour pour 157 lignes...
[2025-06-12T19:50:32.798+0000] {score_missing_articles.py:102} INFO - Exécution de la requête d’UPDATE...
[2025-06-12T19:58:39.355+0000] {local_task_job_runner.py:302} WARNING - State of this instance has been externally set to restarting. Terminating instance.
[2025-06-12T19:58:39.359+0000] {process_utils.py:131} INFO - Sending 15 to group 153. PIDs of all processes in the group: [153]
[2025-06-12T19:58:39.359+0000] {process_utils.py:86} INFO - Sending the signal 15 to group 153
[2025-06-12T19:58:39.360+0000] {taskinstance.py:2450} ERROR - Received SIGTERM. Terminating subprocesses.
[2025-06-12T19:58:39.368+0000] {taskinstance.py:2698} ERROR - Task failed with exception
Traceback (most recent call last):
  File "/home/airflow/.local/lib/python3.10/site-packages/airflow/models/taskinstance.py", line 433, in _execute_task
    result = execute_callable(context=context, **execute_callable_kwargs)
  File "/home/airflow/.local/lib/python3.10/site-packages/airflow/operators/python.py", line 199, in execute
    return_value = self.execute_callable()
  File "/home/airflow/.local/lib/python3.10/site-packages/airflow/operators/python.py", line 216, in execute_callable
    return self.python_callable(*self.op_args, **self.op_kwargs)
  File "/opt/airflow/src/scoring/score_missing_articles.py", line 103, in score_and_update
    logging.info("Exécution de la requête d’UPDATE...")
  File "/home/airflow/.local/lib/python3.10/site-packages/google/cloud/bigquery/client.py", line 3387, in query
    return _job_helpers.query_jobs_insert(
  File "/home/airflow/.local/lib/python3.10/site-packages/google/cloud/bigquery/_job_helpers.py", line 158, in query_jobs_insert
    future = do_query()
  File "/home/airflow/.local/lib/python3.10/site-packages/google/cloud/bigquery/_job_helpers.py", line 135, in do_query
    query_job._begin(retry=retry, timeout=timeout)
  File "/home/airflow/.local/lib/python3.10/site-packages/google/cloud/bigquery/job/query.py", line 1379, in _begin
    super(QueryJob, self)._begin(client=client, retry=retry, timeout=timeout)
  File "/home/airflow/.local/lib/python3.10/site-packages/google/cloud/bigquery/job/base.py", line 740, in _begin
    api_response = client._call_api(
  File "/home/airflow/.local/lib/python3.10/site-packages/google/cloud/bigquery/client.py", line 818, in _call_api
    return call()
  File "/home/airflow/.local/lib/python3.10/site-packages/google/api_core/retry.py", line 372, in retry_wrapped_func
    return retry_target(
  File "/home/airflow/.local/lib/python3.10/site-packages/google/api_core/retry.py", line 236, in retry_target
    time.sleep(sleep)
  File "/home/airflow/.local/lib/python3.10/site-packages/airflow/models/taskinstance.py", line 2452, in signal_handler
    raise AirflowException("Task received SIGTERM signal")
airflow.exceptions.AirflowException: Task received SIGTERM signal
[2025-06-12T19:58:39.394+0000] {taskinstance.py:1138} INFO - Marking task as UP_FOR_RETRY. dag_id=score_missing_articles_pipeline, task_id=score_missing_articles, execution_date=20250612T193103, start_date=20250612T193109, end_date=20250612T195839
[2025-06-12T19:58:39.405+0000] {standard_task_runner.py:107} ERROR - Failed to execute job 351 for task score_missing_articles (Task received SIGTERM signal; 153)
[2025-06-12T19:58:39.934+0000] {process_utils.py:79} INFO - Process psutil.Process(pid=153, status='terminated', exitcode=1, started='19:31:08') (153) terminated with exit code 1
