[2025-06-29T09:00:01.778+0000] {taskinstance.py:1956} INFO - Dependencies all met for dep_context=non-requeueable deps ti=<TaskInstance: rss_ingestion_dag.extract_and_load scheduled__2025-06-29T08:45:00+00:00 [queued]>
[2025-06-29T09:00:01.784+0000] {taskinstance.py:1956} INFO - Dependencies all met for dep_context=requeueable deps ti=<TaskInstance: rss_ingestion_dag.extract_and_load scheduled__2025-06-29T08:45:00+00:00 [queued]>
[2025-06-29T09:00:01.785+0000] {taskinstance.py:2170} INFO - Starting attempt 1 of 1
[2025-06-29T09:00:01.796+0000] {taskinstance.py:2191} INFO - Executing <Task(_PythonDecoratedOperator): extract_and_load> on 2025-06-29 08:45:00+00:00
[2025-06-29T09:00:01.801+0000] {standard_task_runner.py:60} INFO - Started process 89 to run task
[2025-06-29T09:00:01.805+0000] {standard_task_runner.py:87} INFO - Running: ['***', 'tasks', 'run', 'rss_ingestion_dag', 'extract_and_load', 'scheduled__2025-06-29T08:45:00+00:00', '--job-id', '412', '--raw', '--subdir', 'DAGS_FOLDER/rss_ingestion_dag.py', '--cfg-path', '/tmp/tmpis1u3gu5']
[2025-06-29T09:00:01.808+0000] {standard_task_runner.py:88} INFO - Job 412: Subtask extract_and_load
[2025-06-29T09:00:01.860+0000] {task_command.py:423} INFO - Running <TaskInstance: rss_ingestion_dag.extract_and_load scheduled__2025-06-29T08:45:00+00:00 [running]> on host 33c9c5497071
[2025-06-29T09:00:01.930+0000] {taskinstance.py:2480} INFO - Exporting env vars: AIRFLOW_CTX_DAG_OWNER='***' AIRFLOW_CTX_DAG_ID='rss_ingestion_dag' AIRFLOW_CTX_TASK_ID='extract_and_load' AIRFLOW_CTX_EXECUTION_DATE='2025-06-29T08:45:00+00:00' AIRFLOW_CTX_TRY_NUMBER='1' AIRFLOW_CTX_DAG_RUN_ID='scheduled__2025-06-29T08:45:00+00:00'
[2025-06-29T09:00:09.962+0000] {rss_ingestion_dag.py:31} INFO - 0 nouveaux articles sur 0 récupérés (doublons ignorés : 0)
[2025-06-29T09:00:14.043+0000] {connectionpool.py:872} WARNING - Retrying (Retry(total=2, connect=None, read=None, redirect=None, status=None)) after connection broken by 'NameResolutionError("<urllib3.connection.HTTPSConnection object at 0x7e6bf1d371f0>: Failed to resolve 'oauth2.googleapis.com' ([Errno -2] Name or service not known)")': /token
[2025-06-29T09:00:18.046+0000] {connectionpool.py:872} WARNING - Retrying (Retry(total=1, connect=None, read=None, redirect=None, status=None)) after connection broken by 'NameResolutionError("<urllib3.connection.HTTPSConnection object at 0x7e6bf1d35de0>: Failed to resolve 'oauth2.googleapis.com' ([Errno -2] Name or service not known)")': /token
[2025-06-29T09:00:22.046+0000] {connectionpool.py:872} WARNING - Retrying (Retry(total=0, connect=None, read=None, redirect=None, status=None)) after connection broken by 'NameResolutionError("<urllib3.connection.HTTPSConnection object at 0x7e6bf1d37b20>: Failed to resolve 'oauth2.googleapis.com' ([Errno -2] Name or service not known)")': /token
[2025-06-29T09:00:22.089+0000] {taskinstance.py:2698} ERROR - Task failed with exception
Traceback (most recent call last):
  File "/home/airflow/.local/lib/python3.10/site-packages/urllib3/connection.py", line 203, in _new_conn
    sock = connection.create_connection(
  File "/home/airflow/.local/lib/python3.10/site-packages/urllib3/util/connection.py", line 60, in create_connection
    for res in socket.getaddrinfo(host, port, family, socket.SOCK_STREAM):
  File "/usr/local/lib/python3.10/socket.py", line 955, in getaddrinfo
    for res in _socket.getaddrinfo(host, port, family, type, proto, flags):
socket.gaierror: [Errno -2] Name or service not known

The above exception was the direct cause of the following exception:

Traceback (most recent call last):
  File "/home/airflow/.local/lib/python3.10/site-packages/urllib3/connectionpool.py", line 791, in urlopen
    response = self._make_request(
  File "/home/airflow/.local/lib/python3.10/site-packages/urllib3/connectionpool.py", line 492, in _make_request
    raise new_e
  File "/home/airflow/.local/lib/python3.10/site-packages/urllib3/connectionpool.py", line 468, in _make_request
    self._validate_conn(conn)
  File "/home/airflow/.local/lib/python3.10/site-packages/urllib3/connectionpool.py", line 1097, in _validate_conn
    conn.connect()
  File "/home/airflow/.local/lib/python3.10/site-packages/urllib3/connection.py", line 611, in connect
    self.sock = sock = self._new_conn()
  File "/home/airflow/.local/lib/python3.10/site-packages/urllib3/connection.py", line 210, in _new_conn
    raise NameResolutionError(self.host, self, e) from e
urllib3.exceptions.NameResolutionError: <urllib3.connection.HTTPSConnection object at 0x7e6bf1d7cd00>: Failed to resolve 'oauth2.googleapis.com' ([Errno -2] Name or service not known)

The above exception was the direct cause of the following exception:

Traceback (most recent call last):
  File "/home/airflow/.local/lib/python3.10/site-packages/requests/adapters.py", line 486, in send
    resp = conn.urlopen(
  File "/home/airflow/.local/lib/python3.10/site-packages/urllib3/connectionpool.py", line 875, in urlopen
    return self.urlopen(
  File "/home/airflow/.local/lib/python3.10/site-packages/urllib3/connectionpool.py", line 875, in urlopen
    return self.urlopen(
  File "/home/airflow/.local/lib/python3.10/site-packages/urllib3/connectionpool.py", line 875, in urlopen
    return self.urlopen(
  File "/home/airflow/.local/lib/python3.10/site-packages/urllib3/connectionpool.py", line 845, in urlopen
    retries = retries.increment(
  File "/home/airflow/.local/lib/python3.10/site-packages/urllib3/util/retry.py", line 515, in increment
    raise MaxRetryError(_pool, url, reason) from reason  # type: ignore[arg-type]
urllib3.exceptions.MaxRetryError: HTTPSConnectionPool(host='oauth2.googleapis.com', port=443): Max retries exceeded with url: /token (Caused by NameResolutionError("<urllib3.connection.HTTPSConnection object at 0x7e6bf1d7cd00>: Failed to resolve 'oauth2.googleapis.com' ([Errno -2] Name or service not known)"))

During handling of the above exception, another exception occurred:

Traceback (most recent call last):
  File "/home/airflow/.local/lib/python3.10/site-packages/google/auth/transport/requests.py", line 186, in __call__
    response = self.session.request(
  File "/home/airflow/.local/lib/python3.10/site-packages/requests/sessions.py", line 589, in request
    resp = self.send(prep, **send_kwargs)
  File "/home/airflow/.local/lib/python3.10/site-packages/requests/sessions.py", line 703, in send
    r = adapter.send(request, **kwargs)
  File "/home/airflow/.local/lib/python3.10/site-packages/requests/adapters.py", line 519, in send
    raise ConnectionError(e, request=request)
requests.exceptions.ConnectionError: HTTPSConnectionPool(host='oauth2.googleapis.com', port=443): Max retries exceeded with url: /token (Caused by NameResolutionError("<urllib3.connection.HTTPSConnection object at 0x7e6bf1d7cd00>: Failed to resolve 'oauth2.googleapis.com' ([Errno -2] Name or service not known)"))

The above exception was the direct cause of the following exception:

Traceback (most recent call last):
  File "/home/airflow/.local/lib/python3.10/site-packages/airflow/models/taskinstance.py", line 433, in _execute_task
    result = execute_callable(context=context, **execute_callable_kwargs)
  File "/home/airflow/.local/lib/python3.10/site-packages/airflow/decorators/base.py", line 241, in execute
    return_value = super().execute(context)
  File "/home/airflow/.local/lib/python3.10/site-packages/airflow/operators/python.py", line 199, in execute
    return_value = self.execute_callable()
  File "/home/airflow/.local/lib/python3.10/site-packages/airflow/operators/python.py", line 216, in execute_callable
    return self.python_callable(*self.op_args, **self.op_kwargs)
  File "/opt/airflow/dags/rss_ingestion_dag.py", line 35, in extract_and_load
    file_path = upload_to_gcs(articles, bucket_name, prefix)
  File "/opt/airflow/src/utils/gcs_writer.py", line 15, in upload_to_gcs
    blob.upload_from_string(json.dumps(data, ensure_ascii=False, indent=2), content_type='application/json')
  File "/home/airflow/.local/lib/python3.10/site-packages/google/cloud/storage/blob.py", line 3059, in upload_from_string
    self.upload_from_file(
  File "/home/airflow/.local/lib/python3.10/site-packages/google/cloud/storage/blob.py", line 2766, in upload_from_file
    self._prep_and_do_upload(
  File "/home/airflow/.local/lib/python3.10/site-packages/google/cloud/storage/blob.py", line 2607, in _prep_and_do_upload
    created_json = self._do_upload(
  File "/home/airflow/.local/lib/python3.10/site-packages/google/cloud/storage/blob.py", line 2413, in _do_upload
    response = self._do_multipart_upload(
  File "/home/airflow/.local/lib/python3.10/site-packages/google/cloud/storage/blob.py", line 1926, in _do_multipart_upload
    response = upload.transmit(
  File "/home/airflow/.local/lib/python3.10/site-packages/google/resumable_media/requests/upload.py", line 153, in transmit
    return _request_helpers.wait_and_retry(
  File "/home/airflow/.local/lib/python3.10/site-packages/google/resumable_media/requests/_request_helpers.py", line 155, in wait_and_retry
    response = func()
  File "/home/airflow/.local/lib/python3.10/site-packages/google/resumable_media/requests/upload.py", line 145, in retriable_request
    result = transport.request(
  File "/home/airflow/.local/lib/python3.10/site-packages/google/auth/transport/requests.py", line 537, in request
    self.credentials.before_request(auth_request, method, url, request_headers)
  File "/home/airflow/.local/lib/python3.10/site-packages/google/auth/credentials.py", line 228, in before_request
    self._blocking_refresh(request)
  File "/home/airflow/.local/lib/python3.10/site-packages/google/auth/credentials.py", line 191, in _blocking_refresh
    self.refresh(request)
  File "/home/airflow/.local/lib/python3.10/site-packages/google/oauth2/service_account.py", line 441, in refresh
    access_token, expiry, _ = _client.jwt_grant(
  File "/home/airflow/.local/lib/python3.10/site-packages/google/oauth2/_client.py", line 308, in jwt_grant
    response_data = _token_endpoint_request(
  File "/home/airflow/.local/lib/python3.10/site-packages/google/oauth2/_client.py", line 268, in _token_endpoint_request
    response_status_ok, response_data, retryable_error = _token_endpoint_request_no_throw(
  File "/home/airflow/.local/lib/python3.10/site-packages/google/oauth2/_client.py", line 215, in _token_endpoint_request_no_throw
    request_succeeded, response_data, retryable_error = _perform_request()
  File "/home/airflow/.local/lib/python3.10/site-packages/google/oauth2/_client.py", line 191, in _perform_request
    response = request(
  File "/home/airflow/.local/lib/python3.10/site-packages/google/auth/transport/requests.py", line 192, in __call__
    raise new_exc from caught_exc
google.auth.exceptions.TransportError: HTTPSConnectionPool(host='oauth2.googleapis.com', port=443): Max retries exceeded with url: /token (Caused by NameResolutionError("<urllib3.connection.HTTPSConnection object at 0x7e6bf1d7cd00>: Failed to resolve 'oauth2.googleapis.com' ([Errno -2] Name or service not known)"))
[2025-06-29T09:00:22.117+0000] {taskinstance.py:1138} INFO - Marking task as FAILED. dag_id=rss_ingestion_dag, task_id=extract_and_load, execution_date=20250629T084500, start_date=20250629T090001, end_date=20250629T090022
[2025-06-29T09:00:22.131+0000] {standard_task_runner.py:107} ERROR - Failed to execute job 412 for task extract_and_load (HTTPSConnectionPool(host='oauth2.googleapis.com', port=443): Max retries exceeded with url: /token (Caused by NameResolutionError("<urllib3.connection.HTTPSConnection object at 0x7e6bf1d7cd00>: Failed to resolve 'oauth2.googleapis.com' ([Errno -2] Name or service not known)")); 89)
[2025-06-29T09:00:22.173+0000] {local_task_job_runner.py:234} INFO - Task exited with return code 1
[2025-06-29T09:00:22.185+0000] {taskinstance.py:3280} INFO - 0 downstream tasks scheduled from follow-on schedule check
