[2025-06-12T12:23:22.215+0000] {taskinstance.py:1956} INFO - Dependencies all met for dep_context=non-requeueable deps ti=<TaskInstance: score_missing_articles_pipeline.score_missing_articles manual__2025-06-12T12:23:17.023782+00:00 [queued]>
[2025-06-12T12:23:22.222+0000] {taskinstance.py:1956} INFO - Dependencies all met for dep_context=requeueable deps ti=<TaskInstance: score_missing_articles_pipeline.score_missing_articles manual__2025-06-12T12:23:17.023782+00:00 [queued]>
[2025-06-12T12:23:22.223+0000] {taskinstance.py:2170} INFO - Starting attempt 1 of 2
[2025-06-12T12:23:22.235+0000] {taskinstance.py:2191} INFO - Executing <Task(PythonOperator): score_missing_articles> on 2025-06-12 12:23:17.023782+00:00
[2025-06-12T12:23:22.244+0000] {standard_task_runner.py:60} INFO - Started process 57 to run task
[2025-06-12T12:23:22.250+0000] {standard_task_runner.py:87} INFO - Running: ['***', 'tasks', 'run', 'score_missing_articles_pipeline', 'score_missing_articles', 'manual__2025-06-12T12:23:17.023782+00:00', '--job-id', '313', '--raw', '--subdir', 'DAGS_FOLDER/score_missing_dag.py', '--cfg-path', '/tmp/tmpaopeepyz']
[2025-06-12T12:23:22.255+0000] {standard_task_runner.py:88} INFO - Job 313: Subtask score_missing_articles
[2025-06-12T12:23:22.321+0000] {task_command.py:423} INFO - Running <TaskInstance: score_missing_articles_pipeline.score_missing_articles manual__2025-06-12T12:23:17.023782+00:00 [running]> on host ed245cfdc0cc
[2025-06-12T12:23:22.385+0000] {taskinstance.py:2480} INFO - Exporting env vars: AIRFLOW_CTX_DAG_OWNER='***' AIRFLOW_CTX_DAG_ID='score_missing_articles_pipeline' AIRFLOW_CTX_TASK_ID='score_missing_articles' AIRFLOW_CTX_EXECUTION_DATE='2025-06-12T12:23:17.023782+00:00' AIRFLOW_CTX_TRY_NUMBER='1' AIRFLOW_CTX_DAG_RUN_ID='manual__2025-06-12T12:23:17.023782+00:00'
[2025-06-12T13:16:34.232+0000] {taskinstance.py:2698} ERROR - Task failed with exception
Traceback (most recent call last):
  File "/home/airflow/.local/lib/python3.10/site-packages/airflow/models/taskinstance.py", line 433, in _execute_task
    result = execute_callable(context=context, **execute_callable_kwargs)
  File "/home/airflow/.local/lib/python3.10/site-packages/airflow/operators/python.py", line 199, in execute
    return_value = self.execute_callable()
  File "/home/airflow/.local/lib/python3.10/site-packages/airflow/operators/python.py", line 216, in execute_callable
    return self.python_callable(*self.op_args, **self.op_kwargs)
  File "/opt/airflow/src/scoring/score_missing_articles.py", line 40, in score_and_update
    results = client.query(query).result()
  File "/home/airflow/.local/lib/python3.10/site-packages/google/cloud/bigquery/job/query.py", line 1595, in result
    do_get_result()
  File "/home/airflow/.local/lib/python3.10/site-packages/google/api_core/retry.py", line 372, in retry_wrapped_func
    return retry_target(
  File "/home/airflow/.local/lib/python3.10/site-packages/google/api_core/retry.py", line 207, in retry_target
    result = target()
  File "/home/airflow/.local/lib/python3.10/site-packages/google/cloud/bigquery/job/query.py", line 1584, in do_get_result
    super(QueryJob, self).result(retry=retry, timeout=timeout)
  File "/home/airflow/.local/lib/python3.10/site-packages/google/cloud/bigquery/job/base.py", line 971, in result
    return super(_AsyncJob, self).result(timeout=timeout, **kwargs)
  File "/home/airflow/.local/lib/python3.10/site-packages/google/api_core/future/polling.py", line 261, in result
    raise self._exception
google.api_core.exceptions.NotFound: 404 Not found: Table clarifai-news:news_data.rss_article_scores was not found in location europe-west1; reason: notFound, message: Not found: Table clarifai-news:news_data.rss_article_scores was not found in location europe-west1

Location: europe-west1
Job ID: c21f9cfe-cbe9-475e-b67d-31853e8f134c

[2025-06-12T13:16:34.297+0000] {taskinstance.py:1138} INFO - Marking task as UP_FOR_RETRY. dag_id=score_missing_articles_pipeline, task_id=score_missing_articles, execution_date=20250612T122317, start_date=20250612T122322, end_date=20250612T131634
[2025-06-12T13:16:34.348+0000] {standard_task_runner.py:107} ERROR - Failed to execute job 313 for task score_missing_articles (404 Not found: Table clarifai-news:news_data.rss_article_scores was not found in location europe-west1; reason: notFound, message: Not found: Table clarifai-news:news_data.rss_article_scores was not found in location europe-west1

Location: europe-west1
Job ID: c21f9cfe-cbe9-475e-b67d-31853e8f134c
; 57)
[2025-06-12T13:16:34.469+0000] {local_task_job_runner.py:234} INFO - Task exited with return code 1
[2025-06-12T13:16:34.520+0000] {taskinstance.py:3280} INFO - 0 downstream tasks scheduled from follow-on schedule check
