[2025-06-29T08:45:16.041+0000] {taskinstance.py:1956} INFO - Dependencies all met for dep_context=non-requeueable deps ti=<TaskInstance: score_missing_articles_pipeline.score_missing_articles manual__2025-06-29T08:45:10.635858+00:00 [queued]>
[2025-06-29T08:45:16.048+0000] {taskinstance.py:1956} INFO - Dependencies all met for dep_context=requeueable deps ti=<TaskInstance: score_missing_articles_pipeline.score_missing_articles manual__2025-06-29T08:45:10.635858+00:00 [queued]>
[2025-06-29T08:45:16.049+0000] {taskinstance.py:2170} INFO - Starting attempt 1 of 2
[2025-06-29T08:45:16.059+0000] {taskinstance.py:2191} INFO - Executing <Task(PythonOperator): score_missing_articles> on 2025-06-29 08:45:10.635858+00:00
[2025-06-29T08:45:16.067+0000] {standard_task_runner.py:60} INFO - Started process 79 to run task
[2025-06-29T08:45:16.071+0000] {standard_task_runner.py:87} INFO - Running: ['***', 'tasks', 'run', 'score_missing_articles_pipeline', 'score_missing_articles', 'manual__2025-06-29T08:45:10.635858+00:00', '--job-id', '411', '--raw', '--subdir', 'DAGS_FOLDER/score_missing_dag.py', '--cfg-path', '/tmp/tmpo1_c55et']
[2025-06-29T08:45:16.075+0000] {standard_task_runner.py:88} INFO - Job 411: Subtask score_missing_articles
[2025-06-29T08:45:16.124+0000] {task_command.py:423} INFO - Running <TaskInstance: score_missing_articles_pipeline.score_missing_articles manual__2025-06-29T08:45:10.635858+00:00 [running]> on host 33c9c5497071
[2025-06-29T08:45:16.189+0000] {taskinstance.py:2480} INFO - Exporting env vars: AIRFLOW_CTX_DAG_OWNER='***' AIRFLOW_CTX_DAG_ID='score_missing_articles_pipeline' AIRFLOW_CTX_TASK_ID='score_missing_articles' AIRFLOW_CTX_EXECUTION_DATE='2025-06-29T08:45:10.635858+00:00' AIRFLOW_CTX_TRY_NUMBER='1' AIRFLOW_CTX_DAG_RUN_ID='manual__2025-06-29T08:45:10.635858+00:00'
[2025-06-29T08:45:16.190+0000] {score_missing_articles.py:19} INFO - Initialisation du client BigQuery...
[2025-06-29T08:45:16.228+0000] {score_missing_articles.py:32} INFO - Chargement des modèles de langage...
[2025-06-29T08:47:16.965+0000] {score_missing_articles.py:41} INFO - Modèle ClassCat/gpt2-base-french chargé.
[2025-06-29T08:54:49.030+0000] {log.py:232} WARNING - Error while downloading from https://cdn-lfs.hf.co/asi/gpt-fr-cased-base/cd168869a5aabb666963d69ac0be8ccfb49474e75ee11f11c7e29fef6adda2b5?response-content-disposition=inline%3B+filename*%3DUTF-8%27%27pytorch_model.bin%3B+filename%3D%22pytorch_model.bin%22%3B&response-content-type=application%2Foctet-stream&Expires=1751190441&Policy=eyJTdGF0ZW1lbnQiOlt7IkNvbmRpdGlvbiI6eyJEYXRlTGVzc1RoYW4iOnsiQVdTOkVwb2NoVGltZSI6MTc1MTE5MDQ0MX19LCJSZXNvdXJjZSI6Imh0dHBzOi8vY2RuLWxmcy5oZi5jby9hc2kvZ3B0LWZyLWNhc2VkLWJhc2UvY2QxNjg4NjlhNWFhYmI2NjY5NjNkNjlhYzBiZThjY2ZiNDk0NzRlNzVlZTExZjExYzdlMjlmZWY2YWRkYTJiNT9yZXNwb25zZS1jb250ZW50LWRpc3Bvc2l0aW9uPSomcmVzcG9uc2UtY29udGVudC10eXBlPSoifV19&Signature=OHEv1xcUrCnEQVqcJei5lmhE5Z0s8CLhJnANj8FcmD33MS5-eXKhpIy3ncQt3LrPgXlEJFpk4Brl7UGtemt5an4RYs-29fYsmpoSbwr8V67WyrszKYMyNfYnHSUOzD8VYqoZgi9FAWXMcNo3Sbfml90MK2wN%7EJmPb35cquY7yOv7-CjAVLgLPrjsZ8riIYRc9kQe0rbNPOr1FZOS41Y3WebzHXKvhlZ3bWMwYZZV6FSMbGazg%7EwGcyBUSxqWyC4%7E4EGvc5G0S5HG%7E0M9j58bmLH1kZFhK2fONp0muyUEOfJTkK9BTBksTzn7K2Laml9fGSBpCE52cXUXc-GMUHgWTg__&Key-Pair-Id=K3RPWS32NSSJCE: HTTPSConnectionPool(host='cdn-lfs.hf.co', port=443): Read timed out.
Trying to resume download...
[2025-06-29T08:54:49.030+0000] {file_download.py:508} WARNING - Error while downloading from https://cdn-lfs.hf.co/asi/gpt-fr-cased-base/cd168869a5aabb666963d69ac0be8ccfb49474e75ee11f11c7e29fef6adda2b5?response-content-disposition=inline%3B+filename*%3DUTF-8%27%27pytorch_model.bin%3B+filename%3D%22pytorch_model.bin%22%3B&response-content-type=application%2Foctet-stream&Expires=1751190441&Policy=eyJTdGF0ZW1lbnQiOlt7IkNvbmRpdGlvbiI6eyJEYXRlTGVzc1RoYW4iOnsiQVdTOkVwb2NoVGltZSI6MTc1MTE5MDQ0MX19LCJSZXNvdXJjZSI6Imh0dHBzOi8vY2RuLWxmcy5oZi5jby9hc2kvZ3B0LWZyLWNhc2VkLWJhc2UvY2QxNjg4NjlhNWFhYmI2NjY5NjNkNjlhYzBiZThjY2ZiNDk0NzRlNzVlZTExZjExYzdlMjlmZWY2YWRkYTJiNT9yZXNwb25zZS1jb250ZW50LWRpc3Bvc2l0aW9uPSomcmVzcG9uc2UtY29udGVudC10eXBlPSoifV19&Signature=OHEv1xcUrCnEQVqcJei5lmhE5Z0s8CLhJnANj8FcmD33MS5-eXKhpIy3ncQt3LrPgXlEJFpk4Brl7UGtemt5an4RYs-29fYsmpoSbwr8V67WyrszKYMyNfYnHSUOzD8VYqoZgi9FAWXMcNo3Sbfml90MK2wN%7EJmPb35cquY7yOv7-CjAVLgLPrjsZ8riIYRc9kQe0rbNPOr1FZOS41Y3WebzHXKvhlZ3bWMwYZZV6FSMbGazg%7EwGcyBUSxqWyC4%7E4EGvc5G0S5HG%7E0M9j58bmLH1kZFhK2fONp0muyUEOfJTkK9BTBksTzn7K2Laml9fGSBpCE52cXUXc-GMUHgWTg__&Key-Pair-Id=K3RPWS32NSSJCE: HTTPSConnectionPool(host='cdn-lfs.hf.co', port=443): Read timed out.
Trying to resume download...
[2025-06-29T08:54:58.038+0000] {taskinstance.py:2698} ERROR - Task failed with exception
Traceback (most recent call last):
  File "/home/airflow/.local/lib/python3.10/site-packages/urllib3/response.py", line 710, in _error_catcher
    yield
  File "/home/airflow/.local/lib/python3.10/site-packages/urllib3/response.py", line 814, in _raw_read
    data = self._fp_read(amt) if not fp_closed else b""
  File "/home/airflow/.local/lib/python3.10/site-packages/urllib3/response.py", line 799, in _fp_read
    return self._fp.read(amt) if amt is not None else self._fp.read()
  File "/usr/local/lib/python3.10/http/client.py", line 466, in read
    s = self.fp.read(amt)
  File "/usr/local/lib/python3.10/socket.py", line 705, in readinto
    return self._sock.recv_into(b)
  File "/usr/local/lib/python3.10/ssl.py", line 1307, in recv_into
    return self.read(nbytes, buffer)
  File "/usr/local/lib/python3.10/ssl.py", line 1163, in read
    return self._sslobj.read(len, buffer)
TimeoutError: The read operation timed out

The above exception was the direct cause of the following exception:

Traceback (most recent call last):
  File "/home/airflow/.local/lib/python3.10/site-packages/requests/models.py", line 816, in generate
    yield from self.raw.stream(chunk_size, decode_content=True)
  File "/home/airflow/.local/lib/python3.10/site-packages/urllib3/response.py", line 936, in stream
    data = self.read(amt=amt, decode_content=decode_content)
  File "/home/airflow/.local/lib/python3.10/site-packages/urllib3/response.py", line 879, in read
    data = self._raw_read(amt)
  File "/home/airflow/.local/lib/python3.10/site-packages/urllib3/response.py", line 813, in _raw_read
    with self._error_catcher():
  File "/usr/local/lib/python3.10/contextlib.py", line 153, in __exit__
    self.gen.throw(typ, value, traceback)
  File "/home/airflow/.local/lib/python3.10/site-packages/urllib3/response.py", line 715, in _error_catcher
    raise ReadTimeoutError(self._pool, None, "Read timed out.") from e  # type: ignore[arg-type]
urllib3.exceptions.ReadTimeoutError: HTTPSConnectionPool(host='cdn-lfs.hf.co', port=443): Read timed out.

During handling of the above exception, another exception occurred:

Traceback (most recent call last):
  File "/home/airflow/.local/lib/python3.10/site-packages/huggingface_hub/file_download.py", line 494, in http_get
    for chunk in r.iter_content(chunk_size=constants.DOWNLOAD_CHUNK_SIZE):
  File "/home/airflow/.local/lib/python3.10/site-packages/requests/models.py", line 822, in generate
    raise ConnectionError(e)
requests.exceptions.ConnectionError: HTTPSConnectionPool(host='cdn-lfs.hf.co', port=443): Read timed out.

During handling of the above exception, another exception occurred:

Traceback (most recent call last):
  File "/home/airflow/.local/lib/python3.10/site-packages/urllib3/connection.py", line 203, in _new_conn
    sock = connection.create_connection(
  File "/home/airflow/.local/lib/python3.10/site-packages/urllib3/util/connection.py", line 60, in create_connection
    for res in socket.getaddrinfo(host, port, family, socket.SOCK_STREAM):
  File "/usr/local/lib/python3.10/socket.py", line 955, in getaddrinfo
    for res in _socket.getaddrinfo(host, port, family, type, proto, flags):
socket.gaierror: [Errno -3] Temporary failure in name resolution

The above exception was the direct cause of the following exception:

Traceback (most recent call last):
  File "/home/airflow/.local/lib/python3.10/site-packages/urllib3/connectionpool.py", line 791, in urlopen
    response = self._make_request(
  File "/home/airflow/.local/lib/python3.10/site-packages/urllib3/connectionpool.py", line 492, in _make_request
    raise new_e
  File "/home/airflow/.local/lib/python3.10/site-packages/urllib3/connectionpool.py", line 468, in _make_request
    self._validate_conn(conn)
  File "/home/airflow/.local/lib/python3.10/site-packages/urllib3/connectionpool.py", line 1097, in _validate_conn
    conn.connect()
  File "/home/airflow/.local/lib/python3.10/site-packages/urllib3/connection.py", line 611, in connect
    self.sock = sock = self._new_conn()
  File "/home/airflow/.local/lib/python3.10/site-packages/urllib3/connection.py", line 210, in _new_conn
    raise NameResolutionError(self.host, self, e) from e
urllib3.exceptions.NameResolutionError: <urllib3.connection.HTTPSConnection object at 0x7e6b19be3880>: Failed to resolve 'cdn-lfs.hf.co' ([Errno -3] Temporary failure in name resolution)

The above exception was the direct cause of the following exception:

Traceback (most recent call last):
  File "/home/airflow/.local/lib/python3.10/site-packages/requests/adapters.py", line 486, in send
    resp = conn.urlopen(
  File "/home/airflow/.local/lib/python3.10/site-packages/urllib3/connectionpool.py", line 845, in urlopen
    retries = retries.increment(
  File "/home/airflow/.local/lib/python3.10/site-packages/urllib3/util/retry.py", line 515, in increment
    raise MaxRetryError(_pool, url, reason) from reason  # type: ignore[arg-type]
urllib3.exceptions.MaxRetryError: HTTPSConnectionPool(host='cdn-lfs.hf.co', port=443): Max retries exceeded with url: /asi/gpt-fr-cased-base/cd168869a5aabb666963d69ac0be8ccfb49474e75ee11f11c7e29fef6adda2b5?response-content-disposition=inline%3B+filename*%3DUTF-8%27%27pytorch_model.bin%3B+filename%3D%22pytorch_model.bin%22%3B&response-content-type=application%2Foctet-stream&Expires=1751190441&Policy=eyJTdGF0ZW1lbnQiOlt7IkNvbmRpdGlvbiI6eyJEYXRlTGVzc1RoYW4iOnsiQVdTOkVwb2NoVGltZSI6MTc1MTE5MDQ0MX19LCJSZXNvdXJjZSI6Imh0dHBzOi8vY2RuLWxmcy5oZi5jby9hc2kvZ3B0LWZyLWNhc2VkLWJhc2UvY2QxNjg4NjlhNWFhYmI2NjY5NjNkNjlhYzBiZThjY2ZiNDk0NzRlNzVlZTExZjExYzdlMjlmZWY2YWRkYTJiNT9yZXNwb25zZS1jb250ZW50LWRpc3Bvc2l0aW9uPSomcmVzcG9uc2UtY29udGVudC10eXBlPSoifV19&Signature=OHEv1xcUrCnEQVqcJei5lmhE5Z0s8CLhJnANj8FcmD33MS5-eXKhpIy3ncQt3LrPgXlEJFpk4Brl7UGtemt5an4RYs-29fYsmpoSbwr8V67WyrszKYMyNfYnHSUOzD8VYqoZgi9FAWXMcNo3Sbfml90MK2wN~JmPb35cquY7yOv7-CjAVLgLPrjsZ8riIYRc9kQe0rbNPOr1FZOS41Y3WebzHXKvhlZ3bWMwYZZV6FSMbGazg~wGcyBUSxqWyC4~4EGvc5G0S5HG~0M9j58bmLH1kZFhK2fONp0muyUEOfJTkK9BTBksTzn7K2Laml9fGSBpCE52cXUXc-GMUHgWTg__&Key-Pair-Id=K3RPWS32NSSJCE (Caused by NameResolutionError("<urllib3.connection.HTTPSConnection object at 0x7e6b19be3880>: Failed to resolve 'cdn-lfs.hf.co' ([Errno -3] Temporary failure in name resolution)"))

During handling of the above exception, another exception occurred:

Traceback (most recent call last):
  File "/home/airflow/.local/lib/python3.10/site-packages/airflow/models/taskinstance.py", line 433, in _execute_task
    result = execute_callable(context=context, **execute_callable_kwargs)
  File "/home/airflow/.local/lib/python3.10/site-packages/airflow/operators/python.py", line 199, in execute
    return_value = self.execute_callable()
  File "/home/airflow/.local/lib/python3.10/site-packages/airflow/operators/python.py", line 216, in execute_callable
    return self.python_callable(*self.op_args, **self.op_kwargs)
  File "/opt/airflow/src/scoring/score_missing_articles.py", line 38, in score_and_update
    model = GPT2LMHeadModel.from_pretrained(name)
  File "/home/airflow/.local/lib/python3.10/site-packages/transformers/modeling_utils.py", line 309, in _wrapper
    return func(*args, **kwargs)
  File "/home/airflow/.local/lib/python3.10/site-packages/transformers/modeling_utils.py", line 4422, in from_pretrained
    checkpoint_files, sharded_metadata = _get_resolved_checkpoint_files(
  File "/home/airflow/.local/lib/python3.10/site-packages/transformers/modeling_utils.py", line 1053, in _get_resolved_checkpoint_files
    resolved_archive_file = cached_file(
  File "/home/airflow/.local/lib/python3.10/site-packages/transformers/utils/hub.py", line 312, in cached_file
    file = cached_files(path_or_repo_id=path_or_repo_id, filenames=[filename], **kwargs)
  File "/home/airflow/.local/lib/python3.10/site-packages/transformers/utils/hub.py", line 557, in cached_files
    raise e
  File "/home/airflow/.local/lib/python3.10/site-packages/transformers/utils/hub.py", line 470, in cached_files
    hf_hub_download(
  File "/home/airflow/.local/lib/python3.10/site-packages/huggingface_hub/utils/_validators.py", line 114, in _inner_fn
    return fn(*args, **kwargs)
  File "/home/airflow/.local/lib/python3.10/site-packages/huggingface_hub/file_download.py", line 1008, in hf_hub_download
    return _hf_hub_download_to_cache_dir(
  File "/home/airflow/.local/lib/python3.10/site-packages/huggingface_hub/file_download.py", line 1161, in _hf_hub_download_to_cache_dir
    _download_to_tmp_and_move(
  File "/home/airflow/.local/lib/python3.10/site-packages/huggingface_hub/file_download.py", line 1725, in _download_to_tmp_and_move
    http_get(
  File "/home/airflow/.local/lib/python3.10/site-packages/huggingface_hub/file_download.py", line 511, in http_get
    return http_get(
  File "/home/airflow/.local/lib/python3.10/site-packages/huggingface_hub/file_download.py", line 420, in http_get
    r = _request_wrapper(
  File "/home/airflow/.local/lib/python3.10/site-packages/huggingface_hub/file_download.py", line 309, in _request_wrapper
    response = http_backoff(method=method, url=url, **params, retry_on_exceptions=(), retry_on_status_codes=(429,))
  File "/home/airflow/.local/lib/python3.10/site-packages/huggingface_hub/utils/_http.py", line 310, in http_backoff
    response = session.request(method=method, url=url, **kwargs)
  File "/home/airflow/.local/lib/python3.10/site-packages/requests/sessions.py", line 589, in request
    resp = self.send(prep, **send_kwargs)
  File "/home/airflow/.local/lib/python3.10/site-packages/requests/sessions.py", line 703, in send
    r = adapter.send(request, **kwargs)
  File "/home/airflow/.local/lib/python3.10/site-packages/huggingface_hub/utils/_http.py", line 96, in send
    return super().send(request, *args, **kwargs)
  File "/home/airflow/.local/lib/python3.10/site-packages/requests/adapters.py", line 519, in send
    raise ConnectionError(e, request=request)
requests.exceptions.ConnectionError: (MaxRetryError('HTTPSConnectionPool(host=\'cdn-lfs.hf.co\', port=443): Max retries exceeded with url: /asi/gpt-fr-cased-base/cd168869a5aabb666963d69ac0be8ccfb49474e75ee11f11c7e29fef6adda2b5?response-content-disposition=inline%3B+filename*%3DUTF-8%27%27pytorch_model.bin%3B+filename%3D%22pytorch_model.bin%22%3B&response-content-type=application%2Foctet-stream&Expires=1751190441&Policy=eyJTdGF0ZW1lbnQiOlt7IkNvbmRpdGlvbiI6eyJEYXRlTGVzc1RoYW4iOnsiQVdTOkVwb2NoVGltZSI6MTc1MTE5MDQ0MX19LCJSZXNvdXJjZSI6Imh0dHBzOi8vY2RuLWxmcy5oZi5jby9hc2kvZ3B0LWZyLWNhc2VkLWJhc2UvY2QxNjg4NjlhNWFhYmI2NjY5NjNkNjlhYzBiZThjY2ZiNDk0NzRlNzVlZTExZjExYzdlMjlmZWY2YWRkYTJiNT9yZXNwb25zZS1jb250ZW50LWRpc3Bvc2l0aW9uPSomcmVzcG9uc2UtY29udGVudC10eXBlPSoifV19&Signature=OHEv1xcUrCnEQVqcJei5lmhE5Z0s8CLhJnANj8FcmD33MS5-eXKhpIy3ncQt3LrPgXlEJFpk4Brl7UGtemt5an4RYs-29fYsmpoSbwr8V67WyrszKYMyNfYnHSUOzD8VYqoZgi9FAWXMcNo3Sbfml90MK2wN~JmPb35cquY7yOv7-CjAVLgLPrjsZ8riIYRc9kQe0rbNPOr1FZOS41Y3WebzHXKvhlZ3bWMwYZZV6FSMbGazg~wGcyBUSxqWyC4~4EGvc5G0S5HG~0M9j58bmLH1kZFhK2fONp0muyUEOfJTkK9BTBksTzn7K2Laml9fGSBpCE52cXUXc-GMUHgWTg__&Key-Pair-Id=K3RPWS32NSSJCE (Caused by NameResolutionError("<urllib3.connection.HTTPSConnection object at 0x7e6b19be3880>: Failed to resolve \'cdn-lfs.hf.co\' ([Errno -3] Temporary failure in name resolution)"))'), '(Request ID: a2c445de-71c1-4ddb-a4ec-0359ba892ea0)')
[2025-06-29T08:54:58.071+0000] {taskinstance.py:1138} INFO - Marking task as UP_FOR_RETRY. dag_id=score_missing_articles_pipeline, task_id=score_missing_articles, execution_date=20250629T084510, start_date=20250629T084516, end_date=20250629T085458
[2025-06-29T08:54:58.109+0000] {standard_task_runner.py:107} ERROR - Failed to execute job 411 for task score_missing_articles ((MaxRetryError('HTTPSConnectionPool(host=\'cdn-lfs.hf.co\', port=443): Max retries exceeded with url: /asi/gpt-fr-cased-base/cd168869a5aabb666963d69ac0be8ccfb49474e75ee11f11c7e29fef6adda2b5?response-content-disposition=inline%3B+filename*%3DUTF-8%27%27pytorch_model.bin%3B+filename%3D%22pytorch_model.bin%22%3B&response-content-type=application%2Foctet-stream&Expires=1751190441&Policy=eyJTdGF0ZW1lbnQiOlt7IkNvbmRpdGlvbiI6eyJEYXRlTGVzc1RoYW4iOnsiQVdTOkVwb2NoVGltZSI6MTc1MTE5MDQ0MX19LCJSZXNvdXJjZSI6Imh0dHBzOi8vY2RuLWxmcy5oZi5jby9hc2kvZ3B0LWZyLWNhc2VkLWJhc2UvY2QxNjg4NjlhNWFhYmI2NjY5NjNkNjlhYzBiZThjY2ZiNDk0NzRlNzVlZTExZjExYzdlMjlmZWY2YWRkYTJiNT9yZXNwb25zZS1jb250ZW50LWRpc3Bvc2l0aW9uPSomcmVzcG9uc2UtY29udGVudC10eXBlPSoifV19&Signature=OHEv1xcUrCnEQVqcJei5lmhE5Z0s8CLhJnANj8FcmD33MS5-eXKhpIy3ncQt3LrPgXlEJFpk4Brl7UGtemt5an4RYs-29fYsmpoSbwr8V67WyrszKYMyNfYnHSUOzD8VYqoZgi9FAWXMcNo3Sbfml90MK2wN~JmPb35cquY7yOv7-CjAVLgLPrjsZ8riIYRc9kQe0rbNPOr1FZOS41Y3WebzHXKvhlZ3bWMwYZZV6FSMbGazg~wGcyBUSxqWyC4~4EGvc5G0S5HG~0M9j58bmLH1kZFhK2fONp0muyUEOfJTkK9BTBksTzn7K2Laml9fGSBpCE52cXUXc-GMUHgWTg__&Key-Pair-Id=K3RPWS32NSSJCE (Caused by NameResolutionError("<urllib3.connection.HTTPSConnection object at 0x7e6b19be3880>: Failed to resolve \'cdn-lfs.hf.co\' ([Errno -3] Temporary failure in name resolution)"))'), '(Request ID: a2c445de-71c1-4ddb-a4ec-0359ba892ea0)'); 79)
[2025-06-29T08:54:58.168+0000] {local_task_job_runner.py:234} INFO - Task exited with return code 1
[2025-06-29T08:54:58.180+0000] {taskinstance.py:3280} INFO - 0 downstream tasks scheduled from follow-on schedule check
