[2025-06-13T08:22:16.514+0000] {scheduler_job_runner.py:1586} WARNING - Marking task instance <TaskInstance: rss_ingestion_dag.extract_and_load scheduled__2025-06-13T07:45:00+00:00 [queued]> stuck in queued as failed. If the task instance has available retries, it will be retried.
[2025-06-13T08:22:16.706+0000] {scheduler_job_runner.py:781} ERROR - Executor reports task instance <TaskInstance: rss_ingestion_dag.extract_and_load scheduled__2025-06-13T07:45:00+00:00 [queued]> finished (failed) although the task says it's queued. (Info: None) Was the task killed externally?
