[2025-06-12T18:15:00.910+0000] {taskinstance.py:1956} INFO - Dependencies all met for dep_context=non-requeueable deps ti=<TaskInstance: rss_ingestion_dag.extract_and_load scheduled__2025-06-12T18:00:00+00:00 [queued]>
[2025-06-12T18:15:00.916+0000] {taskinstance.py:1956} INFO - Dependencies all met for dep_context=requeueable deps ti=<TaskInstance: rss_ingestion_dag.extract_and_load scheduled__2025-06-12T18:00:00+00:00 [queued]>
[2025-06-12T18:15:00.917+0000] {taskinstance.py:2170} INFO - Starting attempt 1 of 1
[2025-06-12T18:15:00.927+0000] {taskinstance.py:2191} INFO - Executing <Task(_PythonDecoratedOperator): extract_and_load> on 2025-06-12 18:00:00+00:00
[2025-06-12T18:15:00.933+0000] {standard_task_runner.py:60} INFO - Started process 135 to run task
[2025-06-12T18:15:00.937+0000] {standard_task_runner.py:87} INFO - Running: ['***', 'tasks', 'run', 'rss_ingestion_dag', 'extract_and_load', 'scheduled__2025-06-12T18:00:00+00:00', '--job-id', '345', '--raw', '--subdir', 'DAGS_FOLDER/rss_ingestion_dag.py', '--cfg-path', '/tmp/tmpu8z5fwg7']
[2025-06-12T18:15:00.940+0000] {standard_task_runner.py:88} INFO - Job 345: Subtask extract_and_load
[2025-06-12T18:15:00.992+0000] {task_command.py:423} INFO - Running <TaskInstance: rss_ingestion_dag.extract_and_load scheduled__2025-06-12T18:00:00+00:00 [running]> on host ae5839759441
[2025-06-12T18:15:01.057+0000] {taskinstance.py:2480} INFO - Exporting env vars: AIRFLOW_CTX_DAG_OWNER='***' AIRFLOW_CTX_DAG_ID='rss_ingestion_dag' AIRFLOW_CTX_TASK_ID='extract_and_load' AIRFLOW_CTX_EXECUTION_DATE='2025-06-12T18:00:00+00:00' AIRFLOW_CTX_TRY_NUMBER='1' AIRFLOW_CTX_DAG_RUN_ID='scheduled__2025-06-12T18:00:00+00:00'
[2025-06-12T18:15:01.224+0000] {rss_ingestion_dag.py:31} INFO - 28 nouveaux articles sur 28 récupérés (doublons ignorés : 0)
[2025-06-12T18:15:09.182+0000] {taskinstance.py:2698} ERROR - Task failed with exception
Traceback (most recent call last):
  File "/home/airflow/.local/lib/python3.10/site-packages/google/cloud/storage/blob.py", line 2607, in _prep_and_do_upload
    created_json = self._do_upload(
  File "/home/airflow/.local/lib/python3.10/site-packages/google/cloud/storage/blob.py", line 2413, in _do_upload
    response = self._do_multipart_upload(
  File "/home/airflow/.local/lib/python3.10/site-packages/google/cloud/storage/blob.py", line 1926, in _do_multipart_upload
    response = upload.transmit(
  File "/home/airflow/.local/lib/python3.10/site-packages/google/resumable_media/requests/upload.py", line 153, in transmit
    return _request_helpers.wait_and_retry(
  File "/home/airflow/.local/lib/python3.10/site-packages/google/resumable_media/requests/_request_helpers.py", line 178, in wait_and_retry
    raise error
  File "/home/airflow/.local/lib/python3.10/site-packages/google/resumable_media/requests/_request_helpers.py", line 155, in wait_and_retry
    response = func()
  File "/home/airflow/.local/lib/python3.10/site-packages/google/resumable_media/requests/upload.py", line 149, in retriable_request
    self._process_response(result)
  File "/home/airflow/.local/lib/python3.10/site-packages/google/resumable_media/_upload.py", line 125, in _process_response
    _helpers.require_status_code(response, (http.client.OK,), self._get_status_code)
  File "/home/airflow/.local/lib/python3.10/site-packages/google/resumable_media/_helpers.py", line 108, in require_status_code
    raise common.InvalidResponse(
google.resumable_media.common.InvalidResponse: ('Request failed with status code', 503, 'Expected one of', 200)

During handling of the above exception, another exception occurred:

Traceback (most recent call last):
  File "/home/airflow/.local/lib/python3.10/site-packages/airflow/models/taskinstance.py", line 433, in _execute_task
    result = execute_callable(context=context, **execute_callable_kwargs)
  File "/home/airflow/.local/lib/python3.10/site-packages/airflow/decorators/base.py", line 241, in execute
    return_value = super().execute(context)
  File "/home/airflow/.local/lib/python3.10/site-packages/airflow/operators/python.py", line 199, in execute
    return_value = self.execute_callable()
  File "/home/airflow/.local/lib/python3.10/site-packages/airflow/operators/python.py", line 216, in execute_callable
    return self.python_callable(*self.op_args, **self.op_kwargs)
  File "/opt/airflow/dags/rss_ingestion_dag.py", line 35, in extract_and_load
    file_path = upload_to_gcs(articles, bucket_name, prefix)
  File "/opt/airflow/src/utils/gcs_writer.py", line 15, in upload_to_gcs
    blob.upload_from_string(json.dumps(data, ensure_ascii=False, indent=2), content_type='application/json')
  File "/home/airflow/.local/lib/python3.10/site-packages/google/cloud/storage/blob.py", line 3059, in upload_from_string
    self.upload_from_file(
  File "/home/airflow/.local/lib/python3.10/site-packages/google/cloud/storage/blob.py", line 2766, in upload_from_file
    self._prep_and_do_upload(
  File "/home/airflow/.local/lib/python3.10/site-packages/google/cloud/storage/blob.py", line 2625, in _prep_and_do_upload
    _raise_from_invalid_response(exc)
  File "/home/airflow/.local/lib/python3.10/site-packages/google/cloud/storage/blob.py", line 4791, in _raise_from_invalid_response
    raise exceptions.from_http_status(response.status_code, message, response=response)
google.api_core.exceptions.ServiceUnavailable: 503 POST https://storage.googleapis.com/upload/storage/v1/b/clarifai-news-bucket/o?uploadType=multipart: {
  "error": {
    "code": 503,
    "message": "We encountered an internal error. Please try again.",
    "errors": [
      {
        "message": "We encountered an internal error. Please try again.",
        "domain": "global",
        "reason": "backendError"
      }
    ]
  }
}
: ('Request failed with status code', 503, 'Expected one of', <HTTPStatus.OK: 200>)
[2025-06-12T18:15:09.198+0000] {taskinstance.py:1138} INFO - Marking task as FAILED. dag_id=rss_ingestion_dag, task_id=extract_and_load, execution_date=20250612T180000, start_date=20250612T181500, end_date=20250612T181509
[2025-06-12T18:15:09.208+0000] {standard_task_runner.py:107} ERROR - Failed to execute job 345 for task extract_and_load (503 POST https://storage.googleapis.com/upload/storage/v1/b/clarifai-news-bucket/o?uploadType=multipart: {
  "error": {
    "code": 503,
    "message": "We encountered an internal error. Please try again.",
    "errors": [
      {
        "message": "We encountered an internal error. Please try again.",
        "domain": "global",
        "reason": "backendError"
      }
    ]
  }
}
: ('Request failed with status code', 503, 'Expected one of', <HTTPStatus.OK: 200>); 135)
[2025-06-12T18:15:09.253+0000] {local_task_job_runner.py:234} INFO - Task exited with return code 1
[2025-06-12T18:15:09.266+0000] {taskinstance.py:3280} INFO - 0 downstream tasks scheduled from follow-on schedule check
